Workbook

Sheet 摘要
A1: AI 股票預測 — 單次執行結果與真實準確度報告
A2: 產生時間:2026-07-14 21:45 CST|資料:台灣證券交易所(TWSE)官方 API + Yahoo股市交叉驗證|標的:台股6檔權值股|模型:LightGBM 3類(依 repo ml/ 設計)
A4: ★ 給部署決策的一句話:模型樣本外準確度未超越天真基準線(永遠猜上漲/沿用昨日方向),不建議依此上線付費功能。
A6: 關鍵數字(活公式引用進一步工作表)
A7: 指標 | B7: 平衡版1日 | C7: 平衡版5日 | D7: 基準版1日 | E7: 基準版5日
A8: 樣本外準確率(walk-forward) | B8: =AVERAGE(明細平衡版1日!$F$2:$F$412) -> 0.36982968 | C8: =AVERAGE(明細平衡版5日!$F$2:$F$388) -> 0.35658915 | D8: =AVERAGE(明細基準版1日!$F$2:$F$412) -> 0.4136253 | E8: =AVERAGE(明細基準版5日!$F$2:$F$388) -> 0.51421189
A9: 基準線:永遠猜「上漲」 | B9: =COUNTIF(明細平衡版1日!$E$2:$E$412,"上漲")/COUNTA(明細平衡版1日!$E$2:$E$412) -> 0.42822384 | C9: =COUNTIF(明細平衡版5日!$E$2:$E$388,"上漲")/COUNTA(明細平衡版5日!$E$2:$E$388) -> 0.51421189 | D9: =COUNTIF(明細基準版1日!$E$2:$E$412,"上漲")/COUNTA(明細基準版1日!$E$2:$E$412) -> 0.42822384 | E9: =COUNTIF(明細基準版5日!$E$2:$E$388,"上漲")/COUNTA(明細基準版5日!$E$2:$E$388) -> 0.51421189
A10: 模型贏過基準線? | B10: =IF(B8>B9,"是","否") -> 否 | C10: =IF(C8>C9,"是","否") -> 否 | D10: =IF(D8>D9,"是","否") -> 否 | E10: =IF(E8>E9,"是","否") -> 否
A11: 測試樣本數(筆,全為樣本外) | B11: =COUNTA(明細平衡版1日!$E$2:$E$412) -> 411 | C11: =COUNTA(明細平衡版5日!$E$2:$E$388) -> 387 | D11: =COUNTA(明細基準版1日!$E$2:$E$412) -> 411 | E11: =COUNTA(明細基準版5日!$E$2:$E$388) -> 387
A13: 資料真實性:TWSE 日線 × TWSE 即時 API × Yahoo股市 三方核對 7/9 收盤全數一致(詳「資料驗證」表);7/13、7/14 預測於結果實現前產生並以實際收盤驗證(詳「實地驗證」表)。
A14: 工作表導覽:最新預測|準確度指標|混淆矩陣|實地驗證0713_0714|明細×4(1,598筆樣本外預測)|資料驗證|方法與限制

Sheet 明細平衡版1日
A1: 股票代號 | B1: 股票名稱 | C1: 特徵日 | D1: 預測 | E1: 實際 | F1: 正確(1=對) | G1: 實際報酬 | H1: p下跌 | I1: p持平 | J1: p上漲 | K1: 測試月 | L1: 訓練筆數 | M1: 早停輪數
A2: 2308 | B2: 台達電 | C2: 2026-04-01 | D2: 上漲 | E2: 下跌 | F2: =IF(D2=E2,1,0) -> 0 | G2: -0.030508475 | H2: 0.3043812 | I2: 0.32735563 | J2: 0.36826317 | K2: 2026-04 | L2: 857 | M2: 5
A3: 2317 | B3: 鴻海 | C3: 2026-04-01 | D3: 上漲 | E3: 下跌 | F3: =IF(D3=E3,1,0) -> 0 | G3: -0.020304569 | H3: 0.28279666 | I3: 0.34967866 | J3: 0.36752467 | K3: 2026-04 | L3: 857 | M3: 5
A4: 2330 | B4: 台積電 | C4: 2026-04-01 | D4: 上漲 | E4: 下跌 | F4: =IF(D4=E4,1,0) -> 0 | G4: -0.02425876 | H4: 0.28658901 | I4: 0.34586084 | J4: 0.36755016 | K4: 2026-04 | L4: 857 | M4: 5
A5: 2454 | B5: 聯發科 | C5: 2026-04-01 | D5: 上漲 | E5: 持平 | F5: =IF(D5=E5,1,0) -> 0 | G5: 0 | H5: 0.31339523 | I5: 0.32398747 | J5: 0.3626173 | K5: 2026-04 | L5: 857 | M5: 5
A6: 2603 | B6: 長榮 | C6: 2026-04-01 | D6: 上漲 | E6: 下跌 | F6: =IF(D6=E6,1,0) -> 0 | G6: -0.0097799511 | H6: 0.28913105 | I6: 0.33654183 | J6: 0.37432712 | K6: 2026-04 | L6: 857 | M6: 5
A7: 2882 | B7: 國泰金 | C7: 2026-04-01 | D7: 上漲 | E7: 持平 | F7: =IF(D7=E7,1,0) -> 0 | G7: -0.0013908206 | H7: 0.28954014 | I7: 0.3299548 | J7: 0.38050506 | K7: 2026-04 | L7: 857 | M7: 5
A8: 2308 | B8: 台達電 | C8: 2026-04-02 | D8: 上漲 | E8: 上漲 | F8: =IF(D8=E8,1,0) -> 1 | G8: 0.059440559 | H8: 0.32827818 | I8: 0.325607 | J8: 0.34611482 | K8: 2026-04 | L8: 857 | M8: 5
A9: 2317 | B9: 鴻海 | C9: 2026-04-02 | D9: 持平 | E9: 下跌 | F9: =IF(D9=E9,1,0) -> 0 | G9: -0.0051813472 | H9: 0.30358963 | I9: 0.37016944 | J9: 0.32624093 | K9: 2026-04 | L9: 857 | M9: 5
A10: 2330 | B10: 台積電 | C10: 2026-04-02 | D10: 持平 | E10: 上漲 | F10: =IF(D10=E10,1,0) -> 0 | G10: 0.027624309 | H10: 0.30358963 | I10: 0.37016944 | J10: 0.32624093 | K10: 2026-04 | L10: 857 | M10: 5
A11: 2454 | B11: 聯發科 | C11: 2026-04-02 | D11: 上漲 | E11: 持平 | F11: =IF(D11=E11,1,0) -> 0 | G11: 0.0034129693 | H11: 0.30105314 | I11: 0.32636475 | J11: 0.3725821 | K11: 2026-04 | L11: 857 | M11: 5
A12: 2603 | B12: 長榮 | C12: 2026-04-02 | D12: 持平 | E12: 持平 | F12: =IF(D12=E12,1,0) -> 1 | G12: 0.0024691358 | H12: 0.30991496 | I12: 0.35017716 | J12: 0.33990788 | K12: 2026-04 | L12: 857 | M12: 5
A13: 2882 | B13: 國泰金 | C13: 2026-04-02 | D13: 上漲 | E13: 持平 | F13: =IF(D13=E13,1,0) -> 0 | G13: 0.0013927577 | H13: 0.3058717 | I13: 0.33236901 | J13: 0.36175929 | K13: 2026-04 | L13: 857 | M13: 5
... A412: 2882 | B412: 國泰金 | C412: 2026-07-13 | D412: 上漲 | E412: 下跌 | F412: =IF(D412=E412,1,0) -> 0 | G412: -0.006204757 | H412: 0.33442577 | I412: 0.32408415 | J412: 0.34149008 | K412: 2026-07 | L412: 1220 | M412: 1

Sheet 明細平衡版5日
A1: 股票代號 | B1: 股票名稱 | C1: 特徵日 | D1: 預測 | E1: 實際 | F1: 正確(1=對) | G1: 實際報酬 | H1: p下跌 | I1: p持平 | J1: p上漲 | K1: 測試月 | L1: 訓練筆數 | M1: 早停輪數
A2: 2308 | B2: 台達電 | C2: 2026-04-01 | D2: 上漲 | E2: 上漲 | F2: =IF(D2=E2,1,0) -> 1 | G2: 0.17627119 | H2: 0.21472985 | I2: 0.14526772 | J2: 0.64000243 | K2: 2026-04 | L2: 833 | M2: 50
A3: 2317 | B3: 鴻海 | C3: 2026-04-01 | D3: 上漲 | E3: 上漲 | F3: =IF(D3=E3,1,0) -> 1 | G3: 0.017766497 | H3: 0.17261249 | I3: 0.29214583 | J3: 0.53524168 | K3: 2026-04 | L3: 833 | M3: 50
A4: 2330 | B4: 台積電 | C4: 2026-04-01 | D4: 上漲 | E4: 上漲 | F4: =IF(D4=E4,1,0) -> 1 | G4: 0.078167116 | H4: 0.2960785 | I4: 0.25230505 | J4: 0.45161645 | K4: 2026-04 | L4: 833 | M4: 50
A5: 2454 | B5: 聯發科 | C5: 2026-04-01 | D5: 上漲 | E5: 上漲 | F5: =IF(D5=E5,1,0) -> 1 | G5: 0.075085324 | H5: 0.18533984 | I5: 0.20134333 | J5: 0.61331683 | K5: 2026-04 | L5: 833 | M5: 50
A6: 2603 | B6: 長榮 | C6: 2026-04-01 | D6: 下跌 | E6: 持平 | F6: =IF(D6=E6,1,0) -> 0 | G6: -0.0097799511 | H6: 0.43111751 | I6: 0.23762173 | J6: 0.33126076 | K6: 2026-04 | L6: 833 | M6: 50
A7: 2882 | B7: 國泰金 | C7: 2026-04-01 | D7: 下跌 | E7: 上漲 | F7: =IF(D7=E7,1,0) -> 0 | G7: 0.013908206 | H7: 0.48769872 | I7: 0.14449959 | J7: 0.36780169 | K7: 2026-04 | L7: 833 | M7: 50
A8: 2308 | B8: 台達電 | C8: 2026-04-02 | D8: 上漲 | E8: 上漲 | F8: =IF(D8=E8,1,0) -> 1 | G8: 0.21678322 | H8: 0.1773469 | I8: 0.21538637 | J8: 0.60726673 | K8: 2026-04 | L8: 833 | M8: 50
A9: 2317 | B9: 鴻海 | C9: 2026-04-02 | D9: 上漲 | E9: 上漲 | F9: =IF(D9=E9,1,0) -> 1 | G9: 0.03626943 | H9: 0.1470479 | I9: 0.23918213 | J9: 0.61376997 | K9: 2026-04 | L9: 833 | M9: 50
A10: 2330 | B10: 台積電 | C10: 2026-04-02 | D10: 上漲 | E10: 上漲 | F10: =IF(D10=E10,1,0) -> 1 | G10: 0.099447514 | H10: 0.26496422 | I10: 0.34451893 | J10: 0.39051685 | K10: 2026-04 | L10: 833 | M10: 50
A11: 2454 | B11: 聯發科 | C11: 2026-04-02 | D11: 上漲 | E11: 上漲 | F11: =IF(D11=E11,1,0) -> 1 | G11: 0.10580205 | H11: 0.17675456 | I11: 0.20024683 | J11: 0.62299861 | K11: 2026-04 | L11: 833 | M11: 50
A12: 2603 | B12: 長榮 | C12: 2026-04-02 | D12: 下跌 | E12: 下跌 | F12: =IF(D12=E12,1,0) -> 1 | G12: -0.012345679 | H12: 0.39957667 | I12: 0.32818423 | J12: 0.27223911 | K12: 2026-04 | L12: 833 | M12: 50
A13: 2882 | B13: 國泰金 | C13: 2026-04-02 | D13: 下跌 | E13: 持平 | F13: =IF(D13=E13,1,0) -> 0 | G13: 0.0027855153 | H13: 0.54232111 | I13: 0.2055416 | J13: 0.25213729 | K13: 2026-04 | L13: 833 | M13: 50
... A388: 2882 | B388: 國泰金 | C388: 2026-07-06 | D388: 下跌 | E388: 上漲 | F388: =IF(D388=E388,1,0) -> 0 | G388: 0.028907923 | H388: 0.38549767 | I388: 0.24215714 | J388: 0.37234519 | K388: 2026-07 | L388: 1196 | M388: 32

Sheet 明細基準版1日
A1: 股票代號 | B1: 股票名稱 | C1: 特徵日 | D1: 預測 | E1: 實際 | F1: 正確(1=對) | G1: 實際報酬 | H1: p下跌 | I1: p持平 | J1: p上漲 | K1: 測試月 | L1: 訓練筆數 | M1: 早停輪數
A2: 2308 | B2: 台達電 | C2: 2026-04-01 | D2: 上漲 | E2: 下跌 | F2: =IF(D2=E2,1,0) -> 0 | G2: -0.030508475 | H2: 0.34595249 | I2: 0.22606755 | J2: 0.42797996 | K2: 2026-04 | L2: 857 | M2: 1
A3: 2317 | B3: 鴻海 | C3: 2026-04-01 | D3: 上漲 | E3: 下跌 | F3: =IF(D3=E3,1,0) -> 0 | G3: -0.020304569 | H3: 0.34203628 | I3: 0.23482853 | J3: 0.42313519 | K3: 2026-04 | L3: 857 | M3: 1
A4: 2330 | B4: 台積電 | C4: 2026-04-01 | D4: 上漲 | E4: 下跌 | F4: =IF(D4=E4,1,0) -> 0 | G4: -0.02425876 | H4: 0.34203628 | I4: 0.23482853 | J4: 0.42313519 | K4: 2026-04 | L4: 857 | M4: 1
A5: 2454 | B5: 聯發科 | C5: 2026-04-01 | D5: 上漲 | E5: 持平 | F5: =IF(D5=E5,1,0) -> 0 | G5: 0 | H5: 0.34940491 | I5: 0.23383274 | J5: 0.41676235 | K5: 2026-04 | L5: 857 | M5: 1
A6: 2603 | B6: 長榮 | C6: 2026-04-01 | D6: 上漲 | E6: 下跌 | F6: =IF(D6=E6,1,0) -> 0 | G6: -0.0097799511 | H6: 0.34595249 | I6: 0.22606755 | J6: 0.42797996 | K6: 2026-04 | L6: 857 | M6: 1
A7: 2882 | B7: 國泰金 | C7: 2026-04-01 | D7: 上漲 | E7: 持平 | F7: =IF(D7=E7,1,0) -> 0 | G7: -0.0013908206 | H7: 0.33818587 | I7: 0.23620275 | J7: 0.42561138 | K7: 2026-04 | L7: 857 | M7: 1
A8: 2308 | B8: 台達電 | C8: 2026-04-02 | D8: 上漲 | E8: 上漲 | F8: =IF(D8=E8,1,0) -> 1 | G8: 0.059440559 | H8: 0.36324295 | I8: 0.22537563 | J8: 0.41138141 | K8: 2026-04 | L8: 857 | M8: 1
A9: 2317 | B9: 鴻海 | C9: 2026-04-02 | D9: 上漲 | E9: 下跌 | F9: =IF(D9=E9,1,0) -> 0 | G9: -0.0051813472 | H9: 0.36127832 | I9: 0.22956527 | J9: 0.40915641 | K9: 2026-04 | L9: 857 | M9: 1
A10: 2330 | B10: 台積電 | C10: 2026-04-02 | D10: 上漲 | E10: 上漲 | F10: =IF(D10=E10,1,0) -> 1 | G10: 0.027624309 | H10: 0.36127832 | I10: 0.22956527 | J10: 0.40915641 | K10: 2026-04 | L10: 857 | M10: 1
A11: 2454 | B11: 聯發科 | C11: 2026-04-02 | D11: 上漲 | E11: 持平 | F11: =IF(D11=E11,1,0) -> 0 | G11: 0.0034129693 | H11: 0.35586702 | I11: 0.2261268 | J11: 0.41800618 | K11: 2026-04 | L11: 857 | M11: 1
A12: 2603 | B12: 長榮 | C12: 2026-04-02 | D12: 上漲 | E12: 持平 | F12: =IF(D12=E12,1,0) -> 0 | G12: 0.0024691358 | H12: 0.35914346 | I12: 0.23411791 | J12: 0.40673863 | K12: 2026-04 | L12: 857 | M12: 1
A13: 2882 | B13: 國泰金 | C13: 2026-04-02 | D13: 上漲 | E13: 持平 | F13: =IF(D13=E13,1,0) -> 0 | G13: 0.0013927577 | H13: 0.35379545 | I13: 0.23063166 | J13: 0.41557289 | K13: 2026-04 | L13: 857 | M13: 1
... A412: 2882 | B412: 國泰金 | C412: 2026-07-13 | D412: 上漲 | E412: 下跌 | F412: =IF(D412=E412,1,0) -> 0 | G412: -0.006204757 | H412: 0.35873801 | I412: 0.22414659 | J412: 0.4171154 | K412: 2026-07 | L412: 1220 | M412: 1

Sheet 明細基準版5日
A1: 股票代號 | B1: 股票名稱 | C1: 特徵日 | D1: 預測 | E1: 實際 | F1: 正確(1=對) | G1: 實際報酬 | H1: p下跌 | I1: p持平 | J1: p上漲 | K1: 測試月 | L1: 訓練筆數 | M1: 早停輪數
A2: 2308 | B2: 台達電 | C2: 2026-04-01 | D2: 上漲 | E2: 上漲 | F2: =IF(D2=E2,1,0) -> 1 | G2: 0.17627119 | H2: 0.24700546 | I2: 0.21182628 | J2: 0.54116826 | K2: 2026-04 | L2: 833 | M2: 7
A3: 2317 | B3: 鴻海 | C3: 2026-04-01 | D3: 上漲 | E3: 上漲 | F3: =IF(D3=E3,1,0) -> 1 | G3: 0.017766497 | H3: 0.23974282 | I3: 0.26212728 | J3: 0.4981299 | K3: 2026-04 | L3: 833 | M3: 7
A4: 2330 | B4: 台積電 | C4: 2026-04-01 | D4: 上漲 | E4: 上漲 | F4: =IF(D4=E4,1,0) -> 1 | G4: 0.078167116 | H4: 0.30014931 | I4: 0.25913081 | J4: 0.44071989 | K4: 2026-04 | L4: 833 | M4: 7
A5: 2454 | B5: 聯發科 | C5: 2026-04-01 | D5: 上漲 | E5: 上漲 | F5: =IF(D5=E5,1,0) -> 1 | G5: 0.075085324 | H5: 0.24621173 | I5: 0.26950971 | J5: 0.48427856 | K5: 2026-04 | L5: 833 | M5: 7
A6: 2603 | B6: 長榮 | C6: 2026-04-01 | D6: 上漲 | E6: 持平 | F6: =IF(D6=E6,1,0) -> 0 | G6: -0.0097799511 | H6: 0.28406857 | I6: 0.26093184 | J6: 0.45499959 | K6: 2026-04 | L6: 833 | M6: 7
A7: 2882 | B7: 國泰金 | C7: 2026-04-01 | D7: 上漲 | E7: 上漲 | F7: =IF(D7=E7,1,0) -> 1 | G7: 0.013908206 | H7: 0.27419699 | I7: 0.24660948 | J7: 0.47919353 | K7: 2026-04 | L7: 833 | M7: 7
A8: 2308 | B8: 台達電 | C8: 2026-04-02 | D8: 上漲 | E8: 上漲 | F8: =IF(D8=E8,1,0) -> 1 | G8: 0.21678322 | H8: 0.24180229 | I8: 0.2364142 | J8: 0.52178351 | K8: 2026-04 | L8: 833 | M8: 7
A9: 2317 | B9: 鴻海 | C9: 2026-04-02 | D9: 上漲 | E9: 上漲 | F9: =IF(D9=E9,1,0) -> 1 | G9: 0.03626943 | H9: 0.2330791 | I9: 0.2690566 | J9: 0.49786431 | K9: 2026-04 | L9: 833 | M9: 7
A10: 2330 | B10: 台積電 | C10: 2026-04-02 | D10: 上漲 | E10: 上漲 | F10: =IF(D10=E10,1,0) -> 1 | G10: 0.099447514 | H10: 0.28495665 | I10: 0.24429662 | J10: 0.47074673 | K10: 2026-04 | L10: 833 | M10: 7
A11: 2454 | B11: 聯發科 | C11: 2026-04-02 | D11: 上漲 | E11: 上漲 | F11: =IF(D11=E11,1,0) -> 1 | G11: 0.10580205 | H11: 0.2487661 | I11: 0.2619311 | J11: 0.4893028 | K11: 2026-04 | L11: 833 | M11: 7
A12: 2603 | B12: 長榮 | C12: 2026-04-02 | D12: 上漲 | E12: 下跌 | F12: =IF(D12=E12,1,0) -> 0 | G12: -0.012345679 | H12: 0.27397488 | I12: 0.27958104 | J12: 0.44644408 | K12: 2026-04 | L12: 833 | M12: 7
A13: 2882 | B13: 國泰金 | C13: 2026-04-02 | D13: 上漲 | E13: 持平 | F13: =IF(D13=E13,1,0) -> 0 | G13: 0.0027855153 | H13: 0.28133849 | I13: 0.26197395 | J13: 0.45668757 | K13: 2026-04 | L13: 833 | M13: 7
... A388: 2882 | B388: 國泰金 | C388: 2026-07-06 | D388: 上漲 | E388: 上漲 | F388: =IF(D388=E388,1,0) -> 1 | G388: 0.028907923 | H388: 0.30983128 | I388: 0.19406273 | J388: 0.49610599 | K388: 2026-07 | L388: 1196 | M388: 10

Sheet 準確度指標
A1: 走勢預測準確度(walk-forward 樣本外驗證)
A2: 測試期間:2026-04-01 ~ 2026-07-14(逐月擴充視窗重訓,標籤結算日早於測試月才進訓練集,無前視洩漏)
A3: 所有比率皆為活公式,直接統計「明細」工作表;右側附 Python 交叉核算值。
A5: ◆ 平衡版模型.1日水平(n=411)
A6: 指標 | B6: 數值(活公式) | C6: Python核算 | D6: 95%信賴區間下界 | E6: 95%信賴區間上界
A7: 整體準確率(3類) | B7: =AVERAGE(明細平衡版1日!$F$2:$F$412) -> 0.36982968 | C7: 0.36982968 | D7: 0.32456316 | E7: 0.41750707
A8: 平衡準確率(3類recall平均) | B8: =(IFERROR(COUNTIFS(明細平衡版1日!$E$2:$E$412,"下跌",明細平衡版1日!$D$2:$D$412,"下跌")/COUNTIF(明細平衡版1日!$E$2:$E$412,"下跌"),0)+IFERROR(COUNTIFS(明細平衡版1日!$E$2:$E$412,"持平",明細平衡版1日!$D$2:$D$412,"持平")/COUNTIF(明細平衡版1日!$E$2:$E$412,"持平"),0)+IFERROR(COUNTIFS(明細平衡版1日!$E$2:$E$412,"上漲",明細平衡版1日!$D$2:$D$412,"上漲")/COUNTIF(明細平衡版1日!$E$2:$E$412,"上漲"),0))/3 -> 0.35525415 | C8: 0.35525415
A9: 基準線:永遠猜「上漲」 | B9: =COUNTIF(明細平衡版1日!$E$2:$E$412,"上漲")/COUNTA(明細平衡版1日!$E$2:$E$412) -> 0.42822384 | C9: 0.42822384
A10: 基準線:永遠猜「持平」 | B10: =COUNTIF(明細平衡版1日!$E$2:$E$412,"持平")/COUNTA(明細平衡版1日!$E$2:$E$412) -> 0.1946472 | C10: 0.1946472
A11: 基準線:沿用前一日實際方向(n=405) | B11: 0.39012346 | C11: Python計算(同股票前一筆標籤)
A12: 方向性出手數(預測非持平) | B12: =COUNTIF(明細平衡版1日!$D$2:$D$412,"上漲")+COUNTIF(明細平衡版1日!$D$2:$D$412,"下跌") -> 337 | C12: 337
A13: 方向命中率(漲時猜漲/跌時猜跌,報酬符號) | B13: =IFERROR((COUNTIFS(明細平衡版1日!$D$2:$D$412,"上漲",明細平衡版1日!$G$2:$G$412,">0")+COUNTIFS(明細平衡版1日!$D$2:$D$412,"下跌",明細平衡版1日!$G$2:$G$412,"<0"))/(COUNTIF(明細平衡版1日!$D$2:$D$412,"上漲")+COUNTIF(明細平衡版1日!$D$2:$D$412,"下跌")),"—") -> 0.45697329 | C13: 0.45697329 | D13: 0.40457062 | E13: 0.51034587
A14: 「下跌」precision / recall / F1(支持數=155) | B14: =IFERROR(COUNTIFS(明細平衡版1日!$E$2:$E$412,"下跌",明細平衡版1日!$D$2:$D$412,"下跌")/COUNTIF(明細平衡版1日!$D$2:$D$412,"下跌"),"無此類預測") -> 0.34722222 | C14: P=0.347 R=0.323 F1=0.334
A15: 「持平」precision / recall / F1(支持數=80) | B15: =IFERROR(COUNTIFS(明細平衡版1日!$E$2:$E$412,"持平",明細平衡版1日!$D$2:$D$412,"持平")/COUNTIF(明細平衡版1日!$D$2:$D$412,"持平"),"無此類預測") -> 0.32432432 | C15: P=0.324 R=0.300 F1=0.312
A16: 「上漲」precision / recall / F1(支持數=176) | B16: =IFERROR(COUNTIFS(明細平衡版1日!$E$2:$E$412,"上漲",明細平衡版1日!$D$2:$D$412,"上漲")/COUNTIF(明細平衡版1日!$D$2:$D$412,"上漲"),"無此類預測") -> 0.40414508 | C16: P=0.404 R=0.443 F1=0.423
A18: ◆ 平衡版模型.5日水平(n=387)
A19: 指標 | B19: 數值(活公式) | C19: Python核算 | D19: 95%信賴區間下界 | E19: 95%信賴區間上界
A20: 整體準確率(3類) | B20: =AVERAGE(明細平衡版5日!$F$2:$F$388) -> 0.35658915 | C20: 0.35658915 | D20: 0.31048982 | E20: 0.40550766
A21: 平衡準確率(3類recall平均) | B21: =(IFERROR(COUNTIFS(明細平衡版5日!$E$2:$E$388,"下跌",明細平衡版5日!$D$2:$D$388,"下跌")/COUNTIF(明細平衡版5日!$E$2:$E$388,"下跌"),0)+IFERROR(COUNTIFS(明細平衡版5日!$E$2:$E$388,"持平",明細平衡版5日!$D$2:$D$388,"持平")/COUNTIF(明細平衡版5日!$E$2:$E$388,"持平"),0)+IFERROR(COUNTIFS(明細平衡版5日!$E$2:$E$388,"上漲",明細平衡版5日!$D$2:$D$388,"上漲")/COUNTIF(明細平衡版5日!$E$2:$E$388,"上漲"),0))/3 -> 0.30925421 | C21: 0.30925421
A22: 基準線:永遠猜「上漲」 | B22: =COUNTIF(明細平衡版5日!$E$2:$E$388,"上漲")/COUNTA(明細平衡版5日!$E$2:$E$388) -> 0.51421189 | C22: 0.51421189
A23: 基準線:永遠猜「持平」 | B23: =COUNTIF(明細平衡版5日!$E$2:$E$388,"持平")/COUNTA(明細平衡版5日!$E$2:$E$388) -> 0.1627907 | C23: 0.1627907
A24: 基準線:沿用前一日實際方向(n=381) | B24: 0.72178478 | C24: Python計算(同股票前一筆標籤)
A25: 方向性出手數(預測非持平) | B25: =COUNTIF(明細平衡版5日!$D$2:$D$388,"上漲")+COUNTIF(明細平衡版5日!$D$2:$D$388,"下跌") -> 340 | C25: 340
A26: 方向命中率(漲時猜漲/跌時猜跌,報酬符號) | B26: =IFERROR((COUNTIFS(明細平衡版5日!$D$2:$D$388,"上漲",明細平衡版5日!$G$2:$G$388,">0")+COUNTIFS(明細平衡版5日!$D$2:$D$388,"下跌",明細平衡版5日!$G$2:$G$388,"<0"))/(COUNTIF(明細平衡版5日!$D$2:$D$388,"上漲")+COUNTIF(明細平衡版5日!$D$2:$D$388,"下跌")),"—") -> 0.44705882 | C26: 0.44705882 | D26: 0.39509385 | E26: 0.50020678
A27: 「下跌」precision / recall / F1(支持數=125) | B27: =IFERROR(COUNTIFS(明細平衡版5日!$E$2:$E$388,"下跌",明細平衡版5日!$D$2:$D$388,"下跌")/COUNTIF(明細平衡版5日!$D$2:$D$388,"下跌"),"無此類預測") -> 0.23333333 | C27: P=0.233 R=0.280 F1=0.255
A28: 「持平」precision / recall / F1(支持數=63) | B28: =IFERROR(COUNTIFS(明細平衡版5日!$E$2:$E$388,"持平",明細平衡版5日!$D$2:$D$388,"持平")/COUNTIF(明細平衡版5日!$D$2:$D$388,"持平"),"無此類預測") -> 0.25531915 | C28: P=0.255 R=0.190 F1=0.218
A29: 「上漲」precision / recall / F1(支持數=199) | B29: =IFERROR(COUNTIFS(明細平衡版5日!$E$2:$E$388,"上漲",明細平衡版5日!$D$2:$D$388,"上漲")/COUNTIF(明細平衡版5日!$D$2:$D$388,"上漲"),"無此類預測") -> 0.47894737 | C29: P=0.479 R=0.457 F1=0.468
A31: ◆ 基準版模型.1日水平(n=411)
A32: 指標 | B32: 數值(活公式) | C32: Python核算 | D32: 95%信賴區間下界 | E32: 95%信賴區間上界
A33: 整體準確率(3類) | B33: =AVERAGE(明細基準版1日!$F$2:$F$412) -> 0.4136253 | C33: 0.4136253 | D33: 0.36702631 | E33: 0.46182403
A34: 平衡準確率(3類recall平均) | B34: =(IFERROR(COUNTIFS(明細基準版1日!$E$2:$E$412,"下跌",明細基準版1日!$D$2:$D$412,"下跌")/COUNTIF(明細基準版1日!$E$2:$E$412,"下跌"),0)+IFERROR(COUNTIFS(明細基準版1日!$E$2:$E$412,"持平",明細基準版1日!$D$2:$D$412,"持平")/COUNTIF(明細基準版1日!$E$2:$E$412,"持平"),0)+IFERROR(COUNTIFS(明細基準版1日!$E$2:$E$412,"上漲",明細基準版1日!$D$2:$D$412,"上漲")/COUNTIF(明細基準版1日!$E$2:$E$412,"上漲"),0))/3 -> 0.32530547 | C34: 0.32530547
A35: 基準線:永遠猜「上漲」 | B35: =COUNTIF(明細基準版1日!$E$2:$E$412,"上漲")/COUNTA(明細基準版1日!$E$2:$E$412) -> 0.42822384 | C35: 0.42822384
A36: 基準線:永遠猜「持平」 | B36: =COUNTIF(明細基準版1日!$E$2:$E$412,"持平")/COUNTA(明細基準版1日!$E$2:$E$412) -> 0.1946472 | C36: 0.1946472
A37: 基準線:沿用前一日實際方向(n=405) | B37: 0.39012346 | C37: Python計算(同股票前一筆標籤)
A38: 方向性出手數(預測非持平) | B38: =COUNTIF(明細基準版1日!$D$2:$D$412,"上漲")+COUNTIF(明細基準版1日!$D$2:$D$412,"下跌") -> 411 | C38: 411
A39: 方向命中率(漲時猜漲/跌時猜跌,報酬符號) | B39: =IFERROR((COUNTIFS(明細基準版1日!$D$2:$D$412,"上漲",明細基準版1日!$G$2:$G$412,">0")+COUNTIFS(明細基準版1日!$D$2:$D$412,"下跌",明細基準版1日!$G$2:$G$412,"<0"))/(COUNTIF(明細基準版1日!$D$2:$D$412,"上漲")+COUNTIF(明細基準版1日!$D$2:$D$412,"下跌")),"—") -> 0.49148418 | C39: 0.49148418 | D39: 0.44345447 | E39: 0.53967162
A40: 「下跌」precision / recall / F1(支持數=155) | B40: =IFERROR(COUNTIFS(明細基準版1日!$E$2:$E$412,"下跌",明細基準版1日!$D$2:$D$412,"下跌")/COUNTIF(明細基準版1日!$D$2:$D$412,"下跌"),"無此類預測") -> 0.325 | C40: P=0.325 R=0.084 F1=0.133
A41: 「持平」precision / recall / F1(支持數=80) | B41: =IFERROR(COUNTIFS(明細基準版1日!$E$2:$E$412,"持平",明細基準版1日!$D$2:$D$412,"持平")/COUNTIF(明細基準版1日!$D$2:$D$412,"持平"),"無此類預測") -> 無此類預測 | C41: P=無(0次預測) R=0.000
A42: 「上漲」precision / recall / F1(支持數=176) | B42: =IFERROR(COUNTIFS(明細基準版1日!$E$2:$E$412,"上漲",明細基準版1日!$D$2:$D$412,"上漲")/COUNTIF(明細基準版1日!$D$2:$D$412,"上漲"),"無此類預測") -> 0.42318059 | C42: P=0.423 R=0.892 F1=0.574
A44: ◆ 基準版模型.5日水平(n=387)
...

Sheet 混淆矩陣
A1: 混淆矩陣(列=實際,欄=預測;活公式 COUNTIFS 統計明細表)
A3: 平衡版模型.1日水平
A4: 實際\預測 | B4: 預測下跌 | C4: 預測持平 | D4: 預測上漲 | E4: 列合計
A5: 實際下跌 | B5: =COUNTIFS(明細平衡版1日!$E$2:$E$412,"下跌",明細平衡版1日!$D$2:$D$412,"下跌") -> 50 | C5: =COUNTIFS(明細平衡版1日!$E$2:$E$412,"下跌",明細平衡版1日!$D$2:$D$412,"持平") -> 26 | D5: =COUNTIFS(明細平衡版1日!$E$2:$E$412,"下跌",明細平衡版1日!$D$2:$D$412,"上漲") -> 79 | E5: =SUM(B5:D5) -> 155
A6: 實際持平 | B6: =COUNTIFS(明細平衡版1日!$E$2:$E$412,"持平",明細平衡版1日!$D$2:$D$412,"下跌") -> 20 | C6: =COUNTIFS(明細平衡版1日!$E$2:$E$412,"持平",明細平衡版1日!$D$2:$D$412,"持平") -> 24 | D6: =COUNTIFS(明細平衡版1日!$E$2:$E$412,"持平",明細平衡版1日!$D$2:$D$412,"上漲") -> 36 | E6: =SUM(B6:D6) -> 80
A7: 實際上漲 | B7: =COUNTIFS(明細平衡版1日!$E$2:$E$412,"上漲",明細平衡版1日!$D$2:$D$412,"下跌") -> 74 | C7: =COUNTIFS(明細平衡版1日!$E$2:$E$412,"上漲",明細平衡版1日!$D$2:$D$412,"持平") -> 24 | D7: =COUNTIFS(明細平衡版1日!$E$2:$E$412,"上漲",明細平衡版1日!$D$2:$D$412,"上漲") -> 78 | E7: =SUM(B7:D7) -> 176
A8: 欄合計 | B8: =SUM(B5:B7) -> 144 | C8: =SUM(C5:C7) -> 74 | D8: =SUM(D5:D7) -> 193 | E8: =SUM(B8:D8) -> 411
A10: 平衡版模型.5日水平
A11: 實際\預測 | B11: 預測下跌 | C11: 預測持平 | D11: 預測上漲 | E11: 列合計
A12: 實際下跌 | B12: =COUNTIFS(明細平衡版5日!$E$2:$E$388,"下跌",明細平衡版5日!$D$2:$D$388,"下跌") -> 35 | C12: =COUNTIFS(明細平衡版5日!$E$2:$E$388,"下跌",明細平衡版5日!$D$2:$D$388,"持平") -> 16 | D12: =COUNTIFS(明細平衡版5日!$E$2:$E$388,"下跌",明細平衡版5日!$D$2:$D$388,"上漲") -> 74 | E12: =SUM(B12:D12) -> 125
A13: 實際持平 | B13: =COUNTIFS(明細平衡版5日!$E$2:$E$388,"持平",明細平衡版5日!$D$2:$D$388,"下跌") -> 26 | C13: =COUNTIFS(明細平衡版5日!$E$2:$E$388,"持平",明細平衡版5日!$D$2:$D$388,"持平") -> 12 | D13: =COUNTIFS(明細平衡版5日!$E$2:$E$388,"持平",明細平衡版5日!$D$2:$D$388,"上漲") -> 25 | E13: =SUM(B13:D13) -> 63
A14: 實際上漲 | B14: =COUNTIFS(明細平衡版5日!$E$2:$E$388,"上漲",明細平衡版5日!$D$2:$D$388,"下跌") -> 89 | C14: =COUNTIFS(明細平衡版5日!$E$2:$E$388,"上漲",明細平衡版5日!$D$2:$D$388,"持平") -> 19 | D14: =COUNTIFS(明細平衡版5日!$E$2:$E$388,"上漲",明細平衡版5日!$D$2:$D$388,"上漲") -> 91 | E14: =SUM(B14:D14) -> 199
A15: 欄合計 | B15: =SUM(B12:B14) -> 150 | C15: =SUM(C12:C14) -> 47 | D15: =SUM(D12:D14) -> 190 | E15: =SUM(B15:D15) -> 387
A17: 基準版模型.1日水平
A18: 實際\預測 | B18: 預測下跌 | C18: 預測持平 | D18: 預測上漲 | E18: 列合計
A19: 實際下跌 | B19: =COUNTIFS(明細基準版1日!$E$2:$E$412,"下跌",明細基準版1日!$D$2:$D$412,"下跌") -> 13 | C19: =COUNTIFS(明細基準版1日!$E$2:$E$412,"下跌",明細基準版1日!$D$2:$D$412,"持平") -> 0 | D19: =COUNTIFS(明細基準版1日!$E$2:$E$412,"下跌",明細基準版1日!$D$2:$D$412,"上漲") -> 142 | E19: =SUM(B19:D19) -> 155
A20: 實際持平 | B20: =COUNTIFS(明細基準版1日!$E$2:$E$412,"持平",明細基準版1日!$D$2:$D$412,"下跌") -> 8 | C20: =COUNTIFS(明細基準版1日!$E$2:$E$412,"持平",明細基準版1日!$D$2:$D$412,"持平") -> 0 | D20: =COUNTIFS(明細基準版1日!$E$2:$E$412,"持平",明細基準版1日!$D$2:$D$412,"上漲") -> 72 | E20: =SUM(B20:D20) -> 80
A21: 實際上漲 | B21: =COUNTIFS(明細基準版1日!$E$2:$E$412,"上漲",明細基準版1日!$D$2:$D$412,"下跌") -> 19 | C21: =COUNTIFS(明細基準版1日!$E$2:$E$412,"上漲",明細基準版1日!$D$2:$D$412,"持平") -> 0 | D21: =COUNTIFS(明細基準版1日!$E$2:$E$412,"上漲",明細基準版1日!$D$2:$D$412,"上漲") -> 157 | E21: =SUM(B21:D21) -> 176
A22: 欄合計 | B22: =SUM(B19:B21) -> 40 | C22: =SUM(C19:C21) -> 0 | D22: =SUM(D19:D21) -> 371 | E22: =SUM(B22:D22) -> 411
A24: 基準版模型.5日水平
A25: 實際\預測 | B25: 預測下跌 | C25: 預測持平 | D25: 預測上漲 | E25: 列合計
A26: 實際下跌 | B26: =COUNTIFS(明細基準版5日!$E$2:$E$388,"下跌",明細基準版5日!$D$2:$D$388,"下跌") -> 0 | C26: =COUNTIFS(明細基準版5日!$E$2:$E$388,"下跌",明細基準版5日!$D$2:$D$388,"持平") -> 0 | D26: =COUNTIFS(明細基準版5日!$E$2:$E$388,"下跌",明細基準版5日!$D$2:$D$388,"上漲") -> 125 | E26: =SUM(B26:D26) -> 125
A27: 實際持平 | B27: =COUNTIFS(明細基準版5日!$E$2:$E$388,"持平",明細基準版5日!$D$2:$D$388,"下跌") -> 0 | C27: =COUNTIFS(明細基準版5日!$E$2:$E$388,"持平",明細基準版5日!$D$2:$D$388,"持平") -> 0 | D27: =COUNTIFS(明細基準版5日!$E$2:$E$388,"持平",明細基準版5日!$D$2:$D$388,"上漲") -> 63 | E27: =SUM(B27:D27) -> 63
A28: 實際上漲 | B28: =COUNTIFS(明細基準版5日!$E$2:$E$388,"上漲",明細基準版5日!$D$2:$D$388,"下跌") -> 0 | C28: =COUNTIFS(明細基準版5日!$E$2:$E$388,"上漲",明細基準版5日!$D$2:$D$388,"持平") -> 0 | D28: =COUNTIFS(明細基準版5日!$E$2:$E$388,"上漲",明細基準版5日!$D$2:$D$388,"上漲") -> 199 | E28: =SUM(B28:D28) -> 199
A29: 欄合計 | B29: =SUM(B26:B28) -> 0 | C29: =SUM(C26:C28) -> 0 | D29: =SUM(D26:D28) -> 387 | E29: =SUM(B29:D29) -> 387

Sheet 最新預測
A1: 最新一次預測(特徵基準日 2026-07-14 收盤;1日=下一交易日 2026-07-15,5日=5個交易日後)
A2: 重要:依本報告 walk-forward 實測,模型準確度未優於天真基準線;以下預測僅為「執行一次」之輸出示範,不construe為投資建議。
A4: 股票代號 | B4: 股票名稱 | C4: 模型設定 | D4: 預測水平 | E4: 預測方向 | F4: 死區門檻 | G4: p下跌 | H4: p持平 | I4: p上漲 | J4: 說明
A5: 2317 | B5: 鴻海 | C5: 平衡版 | D5: 1日 | E5: 持平 | F5: ±0.5% | G5: 0.32405962 | H5: 0.34664149 | I5: 0.32929889 | J5: 訓練樣本 1274 筆(2025-06-02 ~ 2026-07-13 特徵日)
A6: 2454 | B6: 聯發科 | C6: 平衡版 | D6: 1日 | E6: 持平 | F6: ±0.5% | G6: 0.316445 | H6: 0.34218471 | I6: 0.34137029 | J6: 訓練樣本 1274 筆(2025-06-02 ~ 2026-07-13 特徵日)
A7: 2603 | B7: 長榮 | C7: 平衡版 | D7: 1日 | E7: 持平 | F7: ±0.5% | G7: 0.32684715 | H7: 0.34280403 | I7: 0.33034882 | J7: 訓練樣本 1274 筆(2025-06-02 ~ 2026-07-13 特徵日)
A8: 2330 | B8: 台積電 | C8: 平衡版 | D8: 1日 | E8: 持平 | F8: ±0.5% | G8: 0.32286618 | H8: 0.33949484 | I8: 0.33763897 | J8: 訓練樣本 1274 筆(2025-06-02 ~ 2026-07-13 特徵日)
A9: 2882 | B9: 國泰金 | C9: 平衡版 | D9: 1日 | E9: 上漲 | F9: ±0.5% | G9: 0.33947594 | H9: 0.31741116 | I9: 0.34311291 | J9: 訓練樣本 1274 筆(2025-06-02 ~ 2026-07-13 特徵日)
A10: 2308 | B10: 台達電 | C10: 平衡版 | D10: 1日 | E10: 持平 | F10: ±0.5% | G10: 0.32484089 | H10: 0.34747721 | I10: 0.3276819 | J10: 訓練樣本 1274 筆(2025-06-02 ~ 2026-07-13 特徵日)
A11: 2317 | B11: 鴻海 | C11: 平衡版 | D11: 5日 | E11: 上漲 | F11: ±1.2% | G11: 0.32520278 | H11: 0.24812058 | I11: 0.42667664 | J11: 訓練樣本 1250 筆(2025-06-02 ~ 2026-07-13 特徵日)
A12: 2454 | B12: 聯發科 | C12: 平衡版 | D12: 5日 | E12: 上漲 | F12: ±1.2% | G12: 0.26519801 | H12: 0.25259536 | I12: 0.48220663 | J12: 訓練樣本 1250 筆(2025-06-02 ~ 2026-07-13 特徵日)
A13: 2603 | B13: 長榮 | C13: 平衡版 | D13: 5日 | E13: 上漲 | F13: ±1.2% | G13: 0.33112769 | H13: 0.2523534 | I13: 0.41651891 | J13: 訓練樣本 1250 筆(2025-06-02 ~ 2026-07-13 特徵日)
A14: 2330 | B14: 台積電 | C14: 平衡版 | D14: 5日 | E14: 持平 | F14: ±1.2% | G14: 0.30656367 | H14: 0.35852389 | I14: 0.33491244 | J14: 訓練樣本 1250 筆(2025-06-02 ~ 2026-07-13 特徵日)
A15: 2882 | B15: 國泰金 | C15: 平衡版 | D15: 5日 | E15: 下跌 | F15: ±1.2% | G15: 0.42646708 | H15: 0.2540296 | I15: 0.31950333 | J15: 訓練樣本 1250 筆(2025-06-02 ~ 2026-07-13 特徵日)
A16: 2308 | B16: 台達電 | C16: 平衡版 | D16: 5日 | E16: 上漲 | F16: ±1.2% | G16: 0.31339752 | H16: 0.21120102 | I16: 0.47540146 | J16: 訓練樣本 1250 筆(2025-06-02 ~ 2026-07-13 特徵日)
... A28: 2308 | B28: 台達電 | C28: 基準版 | D28: 5日 | E28: 上漲 | F28: ±1.2% | G28: 0.2832568 | H28: 0.22176418 | I28: 0.49497902 | J28: 訓練樣本 1250 筆(2025-06-02 ~ 2026-07-13 特徵日)
A30: 最高類別機率僅約 0.32~0.48,接近隨機(3類先驗約 0.33),機率本身即顯示訊號薄弱。

Sheet 實地驗證0713_0714
A1: 實地(live)驗證:7月折疊模型(僅用 ≤2026-06-30 標籤訓練)對 7/13、7/14 的預測 vs TWSE 實際收盤
A2: 預測產生於結果實現之前(walk-forward 協議),7/13、7/14 實際數據於 2026-07-14 21:30 CST 自 TWSE 抓取。
A4: 模型設定 | B4: 股票 | C4: 特徵日 | D4: 目標日 | E4: 預測 | F4: 實際 | G4: 實際報酬 | H4: 正確
A5: 平衡版 | B5: 2308 台達電 | C5: 2026-07-09 | D5: 2026-07-13 | E5: 持平 | F5: 上漲 | G5: 0.0053191489 | H5: ✗
A6: 平衡版 | B6: 2317 鴻海 | C6: 2026-07-09 | D6: 2026-07-13 | E6: 持平 | F6: 持平 | G6: -0.0042105263 | H6: ✓
A7: 平衡版 | B7: 2330 台積電 | C7: 2026-07-09 | D7: 2026-07-13 | E7: 下跌 | F7: 上漲 | G7: 0.010351967 | H7: ✗
A8: 平衡版 | B8: 2454 聯發科 | C8: 2026-07-09 | D8: 2026-07-13 | E8: 下跌 | F8: 下跌 | G8: -0.025477707 | H8: ✓
A9: 平衡版 | B9: 2603 長榮 | C9: 2026-07-09 | D9: 2026-07-13 | E9: 持平 | F9: 持平 | G9: 0.0025706941 | H9: ✓
A10: 平衡版 | B10: 2882 國泰金 | C10: 2026-07-09 | D10: 2026-07-13 | E10: 上漲 | F10: 持平 | G10: 0.0041536864 | H10: ✗
A11: 平衡版 | B11: 2308 台達電 | C11: 2026-07-13 | D11: 2026-07-14 | E11: 持平 | F11: 下跌 | G11: -0.018518519 | H11: ✗
A12: 平衡版 | B12: 2317 鴻海 | C12: 2026-07-13 | D12: 2026-07-14 | E12: 持平 | F12: 持平 | G12: -0.0042283298 | H12: ✓
A13: 平衡版 | B13: 2330 台積電 | C13: 2026-07-13 | D13: 2026-07-14 | E13: 下跌 | F13: 下跌 | G13: -0.0081967213 | H13: ✓
A14: 平衡版 | B14: 2454 聯發科 | C14: 2026-07-13 | D14: 2026-07-14 | E14: 上漲 | F14: 下跌 | G14: -0.043137255 | H14: ✗
A15: 平衡版 | B15: 2603 長榮 | C15: 2026-07-13 | D15: 2026-07-14 | E15: 下跌 | F15: 持平 | G15: -0.0025641026 | H15: ✗
A16: 平衡版 | B16: 2882 國泰金 | C16: 2026-07-13 | D16: 2026-07-14 | E16: 上漲 | F16: 下跌 | G16: -0.006204757 | H16: ✗
... A29: 基準版 | B29: 2882 國泰金 | C29: 2026-07-13 | D29: 2026-07-14 | E29: 上漲 | F29: 下跌 | G29: -0.006204757 | H29: ✗
A31: 平衡版 12 次中 5 次正確(41.7%);基準版 12 次中 2 次正確(16.7%)。樣本極小,僅作示意;整體結論請以 411 筆 walk-forward 為準。

Sheet 資料驗證
A1: 資料來源與真實性驗證
A3: 1) 資料涵蓋範圍(TWSE 交易所官方 STOCK_DAY 日線)
A4: 股票 | B4: 筆數 | C4: 起日 | D4: 迄日 | E4: 最後收盤 | F4: 來源 | G4: 抓取時間(CST)
A5: 2330 台積電 | B5: 273 | C5: 2025-06-02 | D5: 2026-07-14 | E5: 2420 | F5: www.twse.com.tw/exchangeReport/STOCK_DAY | G5: 2026-07-10 及 2026-07-14 21:30 補抓
A6: 2317 鴻海 | B6: 272 | C6: 2025-06-02 | D6: 2026-07-14 | E6: 235.5 | F6: www.twse.com.tw/exchangeReport/STOCK_DAY | G6: 2026-07-10 及 2026-07-14 21:30 補抓
A7: 2454 聯發科 | B7: 273 | C7: 2025-06-02 | D7: 2026-07-14 | E7: 3660 | F7: www.twse.com.tw/exchangeReport/STOCK_DAY | G7: 2026-07-10 及 2026-07-14 21:30 補抓
A8: 2882 國泰金 | B8: 273 | C8: 2025-06-02 | D8: 2026-07-14 | E8: 96.1 | F8: www.twse.com.tw/exchangeReport/STOCK_DAY | G8: 2026-07-10 及 2026-07-14 21:30 補抓
A9: 2603 長榮 | B9: 273 | C9: 2025-06-02 | D9: 2026-07-14 | E9: 194.5 | F9: www.twse.com.tw/exchangeReport/STOCK_DAY | G9: 2026-07-10 及 2026-07-14 21:30 補抓
A10: 2308 台達電 | B10: 273 | C10: 2025-06-02 | D10: 2026-07-14 | E10: 1855 | F10: www.twse.com.tw/exchangeReport/STOCK_DAY | G10: 2026-07-10 及 2026-07-14 21:30 補抓
A12: 2) 三方交叉驗證:2026-07-09 收盤(同日三個獨立來源)
A13: 股票 | B13: TWSE日線 STOCK_DAY | C13: TWSE即時 mis.twse | D13: Yahoo股市網頁 | E13: 三者一致 | G13: 查核時間(CST)
A14: 2330 台積電 | B14: 2415 | C14: 2415 | D14: 2415 | E14: =IF(AND(B14=C14,C14=D14),"✓ 一致","✗ 不一致") -> ✓ 一致 | G14: 2026-07-10 20:05-20:07
A15: 2317 鴻海 | B15: 237.5 | C15: 237.5 | D15: 未逐檔查核 | E15: =IF(B15=C15,"✓ 一致(兩源)","✗ 不一致") -> ✓ 一致(兩源) | G15: 2026-07-10 20:05
A16: 2454 聯發科 | B16: 3925 | C16: 3925 | D16: 3925 | E16: =IF(AND(B16=C16,C16=D16),"✓ 一致","✗ 不一致") -> ✓ 一致 | G16: 2026-07-10 20:05-20:09
A17: 2882 國泰金 | B17: 96.3 | C17: 96.3 | D17: 96.3 | E17: =IF(AND(B17=C17,C17=D17),"✓ 一致","✗ 不一致") -> ✓ 一致 | G17: 2026-07-10 20:05-20:08
A18: 2603 長榮 | B18: 194.5 | C18: 194.5 | D18: 未逐檔查核 | E18: =IF(B18=C18,"✓ 一致(兩源)","✗ 不一致") -> ✓ 一致(兩源) | G18: 2026-07-10 20:05
A19: 2308 台達電 | B19: 1880 | C19: 1880 | D19: 未逐檔查核 | E19: =IF(B19=C19,"✓ 一致(兩源)","✗ 不一致") -> ✓ 一致(兩源) | G19: 2026-07-10 20:05
A21: 3) 誠實揭露(抓不到/缺漏的數據)
A22: ‧ Yahoo Finance API(query1/query2.finance.yahoo.com)在本執行環境被網路政策封鎖,無法程式化抓取歷史 OHLCV;故歷史日線改用交易所官方 TWSE STOCK_DAY(權威來源),Yahoo 股市(tw.stock.yahoo.com)網頁即時報價僅用於收盤價交叉驗證(2330/2454/2882 三檔全數吻合,資料時間 2026/07/09 14:30)。
A23: ‧ 三大法人買賣超(T86)與融資融券歷史檔:單日全市場檔案過大,環境限制下無法批量回補一年歷史;依 backend/feature_schema.py 既定規範,法人籌碼特徵以 0.0(中性)代入 = 本次實際未使用。
A24: ‧ K線圖形特徵(YOLO):repo 內無已訓練模型檔(backend/ml_models/ 不存在),圖形特徵以 0.0 代入 = 未使用。
A25: ‧ 2317 鴻海缺 2025-07-30 一筆:TWSE 該月回傳即無此日,非本流程遺失。2026-05 月份首次查詢遭 TWSE 回傳錯誤,已改用替代端點成功補齊並驗證。
A26: ‧ 2026-07-10、07-11、07-12 非交易日(TWSE 即時 API 確認最後交易日為 2026-07-09;7/13 週一恢復交易)。
A27: ‧ 6 檔標的取自 ml/config.py SEED_SYMBOLS 流動性名單前段,涵蓋半導體/電子/IC設計/金融/航運/電源。

Sheet 方法與限制
A1: 方法、程式現況與限制(給部署決策者)
A3: ■ 程式現況:repo 的 AI 預測由 backend/ml_predict.py 服務,需要 backend/ml_models/(manifest.json、pattern_yolo.onnx、lgbm_nextday.txt、lgbm_5day.txt)才能運作;此資料夾目前不存在,ml/ 訓練管線亦僅有 config.py/db.py/universe.py 骨架(缺 labels/features/train/evaluate)。故本次「執行」係依 repo 設計文件重建可執行管線:直接 import backend/indicators.py(30 項技術指標)與 backend/feature_schema.py(特徵順序/缺值=0 規範),標籤採 ml/config.py 死區(1日 ±0.5%、5日 ±1.2%,3類:下跌/持平/上漲),模型採 LightGBM 多分類——與 repo 規劃一致。
A4: ■ 驗證協議:expanding-window walk-forward,逐月重訓,測試月 2026-04 ~ 2026-07;訓練集僅含「標籤結算日早於測試月首日」之樣本,杜絕前視洩漏。測試樣本 1日=411 筆、5日=387 筆,全部為樣本外。
A5: ■ 兩組設定(全部揭露,無挑選):(1)基準版=LightGBM 預設 logloss 早停 → 因驗證切片落在 2026/2-3 修正期,第 1 輪即早停,模型退化為「幾乎全猜上漲」;(2)平衡版=類別平衡權重 + balanced-accuracy 早停(修正類別不平衡)。平衡版係在觀察到基準版退化後加入,兩版測試結果並列呈報。
A6: ■ 核心結論(真實、樣本外):1日水平——平衡版 37.0%(CI 32.5%~41.8%)、基準版 41.4%,皆未優於「永遠猜上漲」43.1%;5日水平——平衡版 35.7%、基準版 51.4%=永遠猜上漲基準線,且遠低於「沿用前一日方向」72.2%(5日報酬重疊自相關使然)。方向命中率(出手時報酬符號)45.7%~58.1%,未穩定超越擲幣。
A7: ■ 判讀:在僅有價量技術指標的條件下,本模型對台股 6 檔大型權值股之次日/5日方向無可部署的預測力。此結果與 ml/config.py 檔頭自述一致(「流動性股票的次日方向,學術上隨機漫步天花板約 50-55%」);repo 期望的 ~75% 需依賴死區設計+籌碼/圖形特徵,本次實測顯示僅靠技術指標遠達不到。
A8: ■ 若要繼續:優先補齊 (1) 三大法人/融資券歷史特徵(建立每日增量收集,如 ml/ 管線原規劃);(2) YOLO 圖形模型訓練;(3) 更長歷史(2年+)與更大股票池;(4) 以「沿用前一日方向」與「永遠猜上漲」為最低上線門檻,加上機率校準與交易成本回測。在未穩定超越上述基準線之前,不建議作為付費功能上線。
A9: ■ 免責聲明:本報告為模型能力評估,非投資建議。過往準確度不代表未來表現。
